<sdf version='1.11'>
  <model name='saye'>
    <link name='base_link'>
      <pose>0 0 0 0 0 0</pose>
      <inertial>
        <pose>-0.00054299999999999997 -0.084945000000000007 0.062329000000000002 0 0 0</pose>
        <mass>41.064</mass>
        <inertia>
          <ixx>0.61539699999999997</ixx>
          <ixy>-0.0240585</ixy>
          <ixz>-0.120749</ixz>
          <iyy>1.7538800000000001</iyy>
          <iyz>-0.0028322</iyz>
          <izz>2.0364100000000001</izz>
        </inertia>
      </inertial>
      <collision name='base_link_collision'>
        <pose>0 0 0.12 0 0 0</pose>
        <geometry>
          <box>
            <size>0.98740000000000006 0.57089999999999996 0.050000000000000003</size>
          </box>
        </geometry>
      </collision>
      <collision name='base_link_collision_bottom'>
        <pose>0 0 0.045999999999999999 0 0 0</pose>
        <geometry>
          <box>
            <size>0.80000000000000004 0.57089999999999996 0.095000000000000001</size>
          </box>
        </geometry>
      </collision>
      <collision name='base_link_collision_1'>
        <pose>0 0 0.18562500000000001 0 0 0</pose>
        <geometry>
          <box>
            <size>0.78991999999999996 0.57089999999999996 0.12375</size>
          </box>
        </geometry>
      </collision>
      <visual name='base_link_visual'>
        <pose>0 0 0 0 0 0</pose>
        <geometry>
          <mesh>
            <scale>1 1 1</scale>
            <uri>meshes/base_link.dae</uri>
          </mesh>
        </geometry>
      </visual>
      <visual name='base_link_fixed_joint_lump__front_bumper_link_visual_3'>
        <pose>0.47999999999999998 0 0.090999999999999998 0 0 0</pose>
        <geometry>
          <mesh>
            <scale>1 1 1</scale>
            <uri>meshes/bumper.dae</uri>
          </mesh>
        </geometry>
      </visual>
      <visual name='base_link_fixed_joint_lump__rear_bumper_link_visual_4'>
        <pose>-0.47999999999999998 0 0.090999999999999998 0 0 3.1415899999999999</pose>
        <geometry>
          <mesh>
            <scale>1 1 1</scale>
            <uri>meshes/bumper.dae</uri>
          </mesh>
        </geometry>
      </visual>
      <visual name='base_link_fixed_joint_lump__top_chassis_link_visual_5'>
        <pose>0 0 0 0 0 0</pose>
        <geometry>
          <mesh>
            <scale>1 1 1</scale>
            <uri>meshes/top_chassis.dae</uri>
          </mesh>
        </geometry>
      </visual>
      <velocity_decay/>
      <self_collide>false</self_collide>
      <enable_wind>false</enable_wind>
      <kinematic>false</kinematic>
    </link>
    <link name='sensor_rack'>
      <inertial>
        <mass>10.40255</mass>
        <inertia>
          <ixx>0.193</ixx>
          <ixy>-0.0030999999999999999</ixy>
          <ixz>0.0091199999999999996</ixz>
          <iyy>0.30099999999999999</iyy>
          <iyz>0.00313</iyz>
          <izz>0.35676000000000002</izz>
        </inertia>
        <pose>0.28000000000000003 0.20000000000000001 0.059999999999999998 0 0 0</pose>
      </inertial>
      <pose>-0.28299999999999997 -0.198243 0.224 -9.9999999999999995e-07 0 -1.2999999999999998e-05</pose>
      <self_collide>false</self_collide>
      <enable_wind>false</enable_wind>
      <kinematic>false</kinematic>

      <collision name='collision_base'>
        <laser_retro>0</laser_retro>
        <max_contacts>10</max_contacts>
        <pose>0.27500000000000002 0.20000000000000001 0.074999999999999997 0 0 0</pose>
        <geometry>
          <box>
            <size>0.56000000000000005 0.40000000000000002 0.14999999999999999</size>
          </box>
        </geometry>
        <surface>
          <friction>
            <ode>
              <mu>1</mu>
              <mu2>1</mu2>
              <fdir1>0 0 0</fdir1>
              <slip1>0</slip1>
              <slip2>0</slip2>
            </ode>
          </friction>
          <contact>
            <collide_without_contact>false</collide_without_contact>
            <collide_without_contact_bitmask>1</collide_without_contact_bitmask>
            <collide_bitmask>1</collide_bitmask>
            <ode>
              <soft_cfm>0</soft_cfm>
              <soft_erp>0.20000000000000001</soft_erp>
              <kp>10000000000000</kp>
              <kd>1</kd>
              <max_vel>0.01</max_vel>
              <min_depth>0</min_depth>
            </ode>
          </contact>
        </surface>
      </collision>
      <collision name='collision_top'>
        <laser_retro>0</laser_retro>
        <max_contacts>10</max_contacts>
        <pose>0.14999999999999999 0.20000000000000001 0.215 0 0 0</pose>
        <geometry>
          <box>
            <size>0.28000000000000003 0.40000000000000002 0.13</size>
          </box>
        </geometry>
        <surface>
          <friction>
            <ode>
              <mu>1</mu>
              <mu2>1</mu2>
              <fdir1>0 0 0</fdir1>
              <slip1>0</slip1>
              <slip2>0</slip2>
            </ode>
          </friction>
          <contact>
            <collide_without_contact>false</collide_without_contact>
            <collide_without_contact_bitmask>1</collide_without_contact_bitmask>
            <collide_bitmask>1</collide_bitmask>
            <ode>
              <soft_cfm>0</soft_cfm>
              <soft_erp>0.20000000000000001</soft_erp>
              <kp>10000000000000</kp>
              <kd>1</kd>
              <max_vel>0.01</max_vel>
              <min_depth>0</min_depth>
            </ode>
          </contact>
        </surface>
      </collision>
      <collision name='collision_laser'>
        <laser_retro>0</laser_retro>
        <max_contacts>10</max_contacts>
        <pose>0.505 0.20000000000000001 0.17000000000000001 0 0.17000000000000004 0</pose>
        <geometry>
          <box>
            <size>0.13500000000000001 0.13 0.13</size>
          </box>
        </geometry>
        <surface>
          <friction>
            <ode>
              <mu>1</mu>
              <mu2>1</mu2>
              <fdir1>0 0 0</fdir1>
              <slip1>0</slip1>
              <slip2>0</slip2>
            </ode>
          </friction>
          <contact>
            <collide_without_contact>false</collide_without_contact>
            <collide_without_contact_bitmask>1</collide_without_contact_bitmask>
            <collide_bitmask>1</collide_bitmask>
            <ode>
              <soft_cfm>0</soft_cfm>
              <soft_erp>0.20000000000000001</soft_erp>
              <kp>10000000000000</kp>
              <kd>1</kd>
              <max_vel>0.01</max_vel>
              <min_depth>0</min_depth>
            </ode>
          </contact>
        </surface>
      </collision>
      <sensor name='imu_sensor' type='imu'>
        <always_on>true</always_on>
        <update_rate>50</update_rate>
        <imu>
          <enable_orientation>false</enable_orientation>
          <angular_velocity>
            <x>
              <noise type='gaussian'>
                <mean>0</mean>
                <stddev>0.0089999999999999993</stddev>
                <bias_mean>0.00075000000000000002</bias_mean>
                <bias_stddev>0.0050000000000000001</bias_stddev>
                <dynamic_bias_stddev>2.0000000000000002e-05</dynamic_bias_stddev>
                <dynamic_bias_correlation_time>400</dynamic_bias_correlation_time>
                <precision>0.00025000000000000001</precision>
              </noise>
            </x>
            <y>
              <noise type='gaussian'>
                <mean>0</mean>
                <stddev>0.0089999999999999993</stddev>
                <bias_mean>0.00075000000000000002</bias_mean>
                <bias_stddev>0.0050000000000000001</bias_stddev>
                <dynamic_bias_stddev>2.0000000000000002e-05</dynamic_bias_stddev>
                <dynamic_bias_correlation_time>400</dynamic_bias_correlation_time>
                <precision>0.00025000000000000001</precision>
              </noise>
            </y>
            <z>
              <noise type='gaussian'>
                <mean>0</mean>
                <stddev>0.0089999999999999993</stddev>
                <bias_mean>0.00075000000000000002</bias_mean>
                <bias_stddev>0.0050000000000000001</bias_stddev>
                <dynamic_bias_stddev>2.0000000000000002e-05</dynamic_bias_stddev>
                <dynamic_bias_correlation_time>400</dynamic_bias_correlation_time>
                <precision>0.00025000000000000001</precision>
              </noise>
            </z>
          </angular_velocity>
          <linear_acceleration>
            <x>
              <noise type='gaussian'>
                <mean>0</mean>
                <stddev>0.021000000000000001</stddev>
                <bias_mean>0.050000000000000003</bias_mean>
                <bias_stddev>0.0074999999999999997</bias_stddev>
                <dynamic_bias_stddev>0.00037500000000000001</dynamic_bias_stddev>
                <dynamic_bias_correlation_time>175</dynamic_bias_correlation_time>
                <precision>0.0050000000000000001</precision>
              </noise>
            </x>
            <y>
              <noise type='gaussian'>
                <mean>0</mean>
                <stddev>0.021000000000000001</stddev>
                <bias_mean>0.050000000000000003</bias_mean>
                <bias_stddev>0.0074999999999999997</bias_stddev>
                <dynamic_bias_stddev>0.00037500000000000001</dynamic_bias_stddev>
                <dynamic_bias_correlation_time>175</dynamic_bias_correlation_time>
                <precision>0.0050000000000000001</precision>
              </noise>
            </y>
            <z>
              <noise type='gaussian'>
                <mean>0</mean>
                <stddev>0.021000000000000001</stddev>
                <bias_mean>0.050000000000000003</bias_mean>
                <bias_stddev>0.0074999999999999997</bias_stddev>
                <dynamic_bias_stddev>0.00037500000000000001</dynamic_bias_stddev>
                <dynamic_bias_correlation_time>175</dynamic_bias_correlation_time>
                <precision>0.0050000000000000001</precision>
              </noise>
            </z>
          </linear_acceleration>
        </imu>
      </sensor>
      <sensor name='camera_0' type='camera'>
        <camera name='camera_0'>
          <horizontal_fov>1.5097100000000001</horizontal_fov>
          <image>
            <width>1920</width>
            <height>1200</height>
            <format>R8G8B8</format>
          </image>
          <clip>
            <near>0.40000000000000002</near>
            <far>300</far>
          </clip>
          <noise>
            <type>gaussian</type>
            <mean>0</mean>
            <stddev>0.0070000000000000001</stddev>
          </noise>
          <lens>
            <intrinsics>
              <fx>1020.51</fx>
              <fy>1020.51</fy>
              <cx>959.5</cx>
              <cy>599.5</cy>
              <s>0</s>
            </intrinsics>
            <type>stereographic</type>
            <scale_to_hfov>true</scale_to_hfov>
          </lens>
        </camera>
        <always_on>true</always_on>
        <update_rate>9</update_rate>
        <visualize>true</visualize>
        <pose>0.34655000000000002 0.075609999999999997 0.08992 0 -0.26000000000000001 -0.57999999999999996</pose>
      </sensor>
      <sensor name='camera_realsense' type='rgbd_camera'>
        <camera name='camera_realsense'>
          <horizontal_fov>1.5184</horizontal_fov>
          <lens>
            <intrinsics>
              <fx>337.22194999999999</fx>
              <fy>337.22194999999999</fy>
              <cx>320.5</cx>
              <cy>240.5</cy>
              <s>0</s>
            </intrinsics>
            <type>stereographic</type>
            <scale_to_hfov>true</scale_to_hfov>
          </lens>
          <distortion>
            <k1>0</k1>
            <k2>0</k2>
            <k3>0</k3>
            <p1>0</p1>
            <p2>0</p2>
            <center>0.5 0.5</center>
          </distortion>
          <image>
            <width>640</width>
            <height>480</height>
            <format>R8G8B8</format>
          </image>
          <clip>
            <near>0.40000000000000002</near>
            <far>300</far>
          </clip>
          <depth_camera>
            <clip>
              <near>0.40000000000000002</near>
              <far>10</far>
            </clip>
            <output>depths</output>
          </depth_camera>
          <noise>
            <type>gaussian</type>
            <mean>0</mean>
            <stddev>0.0070000000000000001</stddev>
          </noise>
        </camera>
        <always_on>true</always_on>
        <update_rate>30</update_rate>
        <pose>0.019230000000000001 0.18204999999999999 0.20000000000000001 0 0.34999999999999998 -3.1400000000000001</pose>
      </sensor>
      <sensor name='gpu_lidar' type='gpu_lidar'>
        <pose>0 0 0 0 0 0</pose>
        <topic>scan</topic>
        <update_rate>10</update_rate>
        <lidar>
          <scan>
            <horizontal>
              <samples>900</samples>
              <resolution>1</resolution>
              <min_angle>-3.1415926540000001</min_angle>
              <max_angle>3.1415926540000001</max_angle>
            </horizontal>
            <vertical>
              <samples>16</samples>
              <resolution>1</resolution>
              <min_angle>-0.26179938800000002</min_angle>
              <max_angle>0.26179938800000002</max_angle>
            </vertical>
          </scan>
          <range>
            <min>0.20000000000000001</min>
            <max>100</max>
            <resolution>0.01</resolution>
          </range>
        </lidar>
        <gz_frame_id>saye/sensor_rack</gz_frame_id>
      </sensor>
    </link>
    <joint name='sensor_rack_joint' type='fixed'>
      <parent>base_link</parent>
      <child>sensor_rack</child>
      <physics>
        <ode>
          <limit>
            <cfm>0</cfm>
            <erp>0.20000000000000001</erp>
          </limit>
          <suspension>
            <cfm>0</cfm>
            <erp>0.20000000000000001</erp>
          </suspension>
        </ode>
      </physics>
    </joint>
    <link name='front_left_wheel_link'>
      <pose>0.25600000000000001 0.28539999999999999 0.032820000000000002 0 0 0</pose>
      <inertial>
        <pose>0 0 0 0 0 0</pose>
        <mass>2.637</mass>
        <inertia>
          <ixx>0.024670000000000001</ixx>
          <ixy>0</ixy>
          <ixz>0</ixz>
          <iyy>0.044110000000000003</iyy>
          <iyz>0</iyz>
          <izz>0.024670000000000001</izz>
        </inertia>
      </inertial>
      <collision name='front_left_wheel_link_collision'>
        <pose>0 0 0 1.5707963267948963 0 0</pose>
        <geometry>
          <cylinder>
            <length>0.1143</length>
            <radius>0.1651</radius>
          </cylinder>
        </geometry>
        <surface>
          <contact>
            <ode>
              <kp>10000000</kp>
              <kd>1</kd>
            </ode>
          </contact>
          <friction>
            <ode>
              <mu>0.5</mu>
              <mu2>1</mu2>
              <slip1>0.00062</slip1>
              <slip2>0</slip2>
              <fdir1>0 0 1</fdir1>
            </ode>
          </friction>
        </surface>
      </collision>
      <visual name='front_left_wheel_link_visual'>
        <pose>0 0 0 0 0 0</pose>
        <geometry>
          <mesh>
            <scale>1 1 1</scale>
            <uri>meshes/wheel.dae</uri>
          </mesh>
        </geometry>
      </visual>
      <gravity>true</gravity>
      <velocity_decay/>
    </link>
    <joint name='front_left_wheel_joint' type='revolute'>
      <child>front_left_wheel_link</child>
      <parent>base_link</parent>
      <axis>
        <xyz>0 1 0</xyz>
        <limit>
          <lower>-10000000000000000</lower>
          <upper>10000000000000000</upper>
        </limit>
        <dynamics>
          <spring_reference>0</spring_reference>
          <spring_stiffness>0</spring_stiffness>
        </dynamics>
        <use_parent_model_frame>1</use_parent_model_frame>
      </axis>
    </joint>
    <link name='front_right_wheel_link'>
      <pose>0.25600000000000001 -0.28539999999999999 0.032820000000000002 0 0 0</pose>
      <inertial>
        <pose>0 0 0 0 0 0</pose>
        <mass>2.637</mass>
        <inertia>
          <ixx>0.024670000000000001</ixx>
          <ixy>0</ixy>
          <ixz>0</ixz>
          <iyy>0.044110000000000003</iyy>
          <iyz>0</iyz>
          <izz>0.024670000000000001</izz>
        </inertia>
      </inertial>
      <collision name='front_right_wheel_link_collision'>
        <pose>0 0 0 1.5707963267948963 0 0</pose>
        <geometry>
          <cylinder>
            <length>0.1143</length>
            <radius>0.1651</radius>
          </cylinder>
        </geometry>
        <surface>
          <contact>
            <ode>
              <kp>10000000</kp>
              <kd>1</kd>
            </ode>
          </contact>
          <friction>
            <ode>
              <mu>0.5</mu>
              <mu2>1</mu2>
              <slip1>0.00062</slip1>
              <slip2>0</slip2>
              <fdir1>0 0 1</fdir1>
            </ode>
          </friction>
        </surface>
      </collision>
      <visual name='front_right_wheel_link_visual'>
        <pose>0 0 0 0 0 0</pose>
        <geometry>
          <mesh>
            <scale>1 1 1</scale>
            <uri>meshes/wheel.dae</uri>
          </mesh>
        </geometry>
      </visual>
      <gravity>true</gravity>
      <velocity_decay/>
    </link>
    <joint name='front_right_wheel_joint' type='revolute'>
      <child>front_right_wheel_link</child>
      <parent>base_link</parent>
      <axis>
        <xyz>0 1 0</xyz>
        <limit>
          <lower>-10000000000000000</lower>
          <upper>10000000000000000</upper>
        </limit>
        <dynamics>
          <spring_reference>0</spring_reference>
          <spring_stiffness>0</spring_stiffness>
        </dynamics>
        <use_parent_model_frame>1</use_parent_model_frame>
      </axis>
    </joint>
    <link name='rear_left_wheel_link'>
      <pose>-0.25600000000000001 0.28539999999999999 0.032820000000000002 0 0 0</pose>
      <inertial>
        <pose>0 0 0 0 0 0</pose>
        <mass>2.637</mass>
        <inertia>
          <ixx>0.024670000000000001</ixx>
          <ixy>0</ixy>
          <ixz>0</ixz>
          <iyy>0.044110000000000003</iyy>
          <iyz>0</iyz>
          <izz>0.024670000000000001</izz>
        </inertia>
      </inertial>
      <collision name='rear_left_wheel_link_collision'>
        <pose>0 0 0 1.5707963267948963 0 0</pose>
        <geometry>
          <cylinder>
            <length>0.1143</length>
            <radius>0.1651</radius>
          </cylinder>
        </geometry>
        <surface>
          <contact>
            <ode>
              <kp>10000000</kp>
              <kd>1</kd>
            </ode>
          </contact>
          <friction>
            <ode>
              <mu>0.5</mu>
              <mu2>1</mu2>
              <slip1>0.00062</slip1>
              <slip2>0</slip2>
              <fdir1>0 0 1</fdir1>
            </ode>
          </friction>
        </surface>
      </collision>
      <visual name='rear_left_wheel_link_visual'>
        <pose>0 0 0 0 0 0</pose>
        <geometry>
          <mesh>
            <scale>1 1 1</scale>
            <uri>meshes/wheel.dae</uri>
          </mesh>
        </geometry>
      </visual>
      <gravity>true</gravity>
      <velocity_decay/>
    </link>
    <joint name='rear_left_wheel_joint' type='revolute'>
      <child>rear_left_wheel_link</child>
      <parent>base_link</parent>
      <axis>
        <xyz>0 1 0</xyz>
        <limit>
          <lower>-10000000000000000</lower>
          <upper>10000000000000000</upper>
        </limit>
        <dynamics>
          <spring_reference>0</spring_reference>
          <spring_stiffness>0</spring_stiffness>
        </dynamics>
        <use_parent_model_frame>1</use_parent_model_frame>
      </axis>
    </joint>
    <link name='rear_right_wheel_link'>
      <pose>-0.25600000000000001 -0.28539999999999999 0.032820000000000002 0 0 0</pose>
      <inertial>
        <pose>0 0 0 0 0 0</pose>
        <mass>2.637</mass>
        <inertia>
          <ixx>0.024670000000000001</ixx>
          <ixy>0</ixy>
          <ixz>0</ixz>
          <iyy>0.044110000000000003</iyy>
          <iyz>0</iyz>
          <izz>0.024670000000000001</izz>
        </inertia>
      </inertial>
      <collision name='rear_right_wheel_link_collision'>
        <pose>0 0 0 1.5707963267948963 0 0</pose>
        <geometry>
          <cylinder>
            <length>0.1143</length>
            <radius>0.1651</radius>
          </cylinder>
        </geometry>
        <surface>
          <contact>
            <ode>
              <kp>10000000</kp>
              <kd>1</kd>
            </ode>
          </contact>
          <friction>
            <ode>
              <mu>0.5</mu>
              <mu2>1</mu2>
              <slip1>0.00062</slip1>
              <slip2>0</slip2>
              <fdir1>0 0 1</fdir1>
            </ode>
          </friction>
        </surface>
      </collision>
      <visual name='rear_right_wheel_link_visual'>
        <pose>0 0 0 0 0 0</pose>
        <geometry>
          <mesh>
            <scale>1 1 1</scale>
            <uri>meshes/wheel.dae</uri>
          </mesh>
        </geometry>
      </visual>
      <gravity>true</gravity>
      <velocity_decay/>
    </link>
    <joint name='rear_right_wheel_joint' type='revolute'>
      <child>rear_right_wheel_link</child>
      <parent>base_link</parent>
      <axis>
        <xyz>0 1 0</xyz>
        <limit>
          <lower>-10000000000000000</lower>
          <upper>10000000000000000</upper>
        </limit>
        <dynamics>
          <spring_reference>0</spring_reference>
          <spring_stiffness>0</spring_stiffness>
        </dynamics>
        <use_parent_model_frame>1</use_parent_model_frame>
      </axis>
    </joint>
    <plugin name='gz::sim::systems::DiffDrive' filename='gz-sim-diff-drive-system'>
      <left_joint>rear_left_wheel_joint</left_joint>
      <right_joint>rear_right_wheel_joint</right_joint>
      <left_joint_2>front_left_wheel_joint</left_joint_2>
      <right_joint_2>front_right_wheel_joint</right_joint_2>
      <wheel_separation>0.5605</wheel_separation>
      <wheel_radius>0.195</wheel_radius>
      <odom_publish_frequency>1</odom_publish_frequency>
      <topic>cmd_vel</topic>
      <max_linear_velocity>2.5</max_linear_velocity>
      <min_linear_velocity>-2.5</min_linear_velocity>
      <max_angular_velocity>2.5</max_angular_velocity>
      <min_angular_velocity>-2.5</min_angular_velocity>
    </plugin>
    <static>false</static>
  </model>
</sdf>
